#VRML_SIM R2019a utf8
WorldInfo {
}
Viewpoint {
  orientation 0.9003356218583676 -0.4102254675400342 -0.14529567713620015 5.533591368056553
  position 0.1319099546452345 0.5566869009362236 0.6045767482208985
}
TexturedBackground {
}
TexturedBackgroundLight {
}
Floor {
}
Robot {
  translation 0 0.075 0
  children [
    DEF bot Group {
      children [
        Transform {
          translation 0.1075 -0.0575 0
          rotation 1 0 0 1.5707963220000003
          children [
            Shape {
              appearance Appearance {
                material Material {
                  diffuseColor 0 1 0.5
                }
              }
              geometry Sphere {
                radius 0.0175
              }
            }
          ]
          rotationStep 0
        }
        DEF Caja Shape {
          appearance DEF Color_1 Appearance {
            material Material {
              diffuseColor 0 0.5 1
            }
          }
          geometry Box {
            size 0.25 0.08 0.1
          }
        }
      ]
    }
    HingeJoint {
      jointParameters HingeJointParameters {
        axis 0 0 1
        anchor -0.05 0 0.065
      }
      device [
        Brake {
        }
        RotationalMotor {
          name "motor_right"
          maxVelocity 523.5987
          maxTorque 0.03
        }
      ]
      endPoint Solid {
        translation -0.05 0 0.065
        rotation 1 0 0 1.5707963220000003
        children [
          DEF Wheel Shape {
            appearance Appearance {
              material Material {
                diffuseColor 1 0 0
              }
            }
            geometry Cylinder {
              height 0.03
              radius 0.075
            }
          }
        ]
        boundingObject USE Wheel
        physics Physics {
        }
      }
    }
    HingeJoint {
      jointParameters HingeJointParameters {
        axis 0 0 1
        anchor -0.05 0 -0.065
      }
      device [
        RotationalMotor {
          name "motor_left"
          maxVelocity 523.5987
          maxTorque 0.03
        }
      ]
      endPoint Solid {
        translation -0.05 0 -0.065
        rotation 1 0 0 1.5707963220000003
        children [
          USE Wheel
        ]
        name "solid(1)"
        boundingObject USE Wheel
        physics Physics {
        }
      }
    }
  ]
  boundingObject USE bot
  physics Physics {
  }
}
