#VRML_SIM R2019a utf8
WorldInfo {
}
Viewpoint {
  orientation -0.10707106942041855 -0.9882422117865431 -0.10914722596754013 1.6018236585737355
  position -0.8627353634976419 0.48012278265499564 -0.18936795770473516
}
TexturedBackground {
}
TexturedBackgroundLight {
}
Floor {
}
Robot {
  translation 0 0.0799999921645342 0
  rotation 0.0025411727235561473 0.06735798175856685 -0.997725636001502 0.00044359830550598245
  children [
    DEF bot Group {
      children [
        Transform {
          translation 0.1075 -0.0575 0
          rotation 1 0 0 1.5707963220000003
          children [
            Shape {
              appearance Appearance {
                material Material {
                  diffuseColor 0 1 0.5
                }
              }
              geometry Sphere {
                radius 0.0175
              }
            }
          ]
          rotationStep 0
        }
        DEF Caja Shape {
          appearance DEF Color_1 Appearance {
            material Material {
              diffuseColor 0 0.5 1
            }
          }
          geometry Box {
            size 0.25 0.08 0.1
          }
        }
      ]
    }
    HingeJoint {
      jointParameters HingeJointParameters {
        axis 0 0 1
        anchor -0.05 0 0.065
      }
      device [
        PositionSensor {
          resolution 1
        }
        RotationalMotor {
          name "motor_right"
          consumptionFactor 300
          maxVelocity 52.3598775
          maxTorque 0.593170353999997
        }
      ]
      endPoint Solid {
        translation -0.05 0 0.065
        rotation 1 0 0 1.5707963220000003
        children [
          DEF Wheel Shape {
            appearance Appearance {
              material Material {
                diffuseColor 1 0 0
              }
            }
            geometry Cylinder {
              height 0.03
              radius 0.075
            }
          }
        ]
        boundingObject USE Wheel
        physics Physics {
        }
      }
    }
    HingeJoint {
      jointParameters HingeJointParameters {
        axis 0 0 1
        anchor -0.05 0 -0.065
      }
      device [
        RotationalMotor {
          name "motor_left"
          consumptionFactor 300
          maxVelocity 52.3598775
          maxTorque 0.593170353999997
        }
      ]
      endPoint Solid {
        translation -0.05 0 -0.065
        rotation 1 0 0 1.5707963220000003
        children [
          USE Wheel
        ]
        name "solid(1)"
        boundingObject USE Wheel
        physics Physics {
        }
      }
    }
    DistanceSensor {
      translation 0.125 0 0
      children [
        Shape {
          geometry Box {
            size 0.01 0.01 0.01
          }
        }
      ]
      lookupTable [
        0 0 0
        0.02 0 0
        5 1660 0
      ]
      type "sonar"
      resolution 1
    }
  ]
  boundingObject USE bot
  physics Physics {
  }
}
